Traceback (most recent call last):
  File "/home/thien/miniconda3/envs/jupyterbook/lib/python3.11/site-packages/jupyter_cache/executors/utils.py", line 58, in single_nb_execution
    executenb(
  File "/home/thien/miniconda3/envs/jupyterbook/lib/python3.11/site-packages/nbclient/client.py", line 1305, in execute
    return NotebookClient(nb=nb, resources=resources, km=km, **kwargs).execute()
           ^^^^^^^^^^^^^^^^^^^^^^^^^^^^^^^^^^^^^^^^^^^^^^^^^^^^^^^^^^^^^^^^^^^^^
  File "/home/thien/miniconda3/envs/jupyterbook/lib/python3.11/site-packages/jupyter_core/utils/__init__.py", line 166, in wrapped
    return loop.run_until_complete(inner)
           ^^^^^^^^^^^^^^^^^^^^^^^^^^^^^^
  File "/home/thien/miniconda3/envs/jupyterbook/lib/python3.11/asyncio/base_events.py", line 653, in run_until_complete
    return future.result()
           ^^^^^^^^^^^^^^^
  File "/home/thien/miniconda3/envs/jupyterbook/lib/python3.11/site-packages/nbclient/client.py", line 705, in async_execute
    await self.async_execute_cell(
  File "/home/thien/miniconda3/envs/jupyterbook/lib/python3.11/site-packages/nbclient/client.py", line 1058, in async_execute_cell
    await self._check_raise_for_error(cell, cell_index, exec_reply)
  File "/home/thien/miniconda3/envs/jupyterbook/lib/python3.11/site-packages/nbclient/client.py", line 914, in _check_raise_for_error
    raise CellExecutionError.from_cell_and_msg(cell, exec_reply_content)
nbclient.exceptions.CellExecutionError: An error occurred while executing the following cell:
------------------
corop = json.load(open('coropgebied_gegeneraliseerd_2021.geojson', 'r'))
for feature in corop['features']:
  feature['id'] = feature['properties']['statcode']
df2 = pd.read_csv('Corop_grijzedruk.csv')
fig2 = px.choropleth(df2, locations='RegioS', geojson=corop, color='GrijzeDruk_24')
fig2.update_geos(fitbounds="locations")                        
fig2.show()

------------------


[0;31m---------------------------------------------------------------------------[0m
[0;31mFileNotFoundError[0m                         Traceback (most recent call last)
Cell [0;32mIn[2], line 1[0m
[0;32m----> 1[0m corop [38;5;241m=[39m json[38;5;241m.[39mload([38;5;28;43mopen[39;49m[43m([49m[38;5;124;43m'[39;49m[38;5;124;43mcoropgebied_gegeneraliseerd_2021.geojson[39;49m[38;5;124;43m'[39;49m[43m,[49m[43m [49m[38;5;124;43m'[39;49m[38;5;124;43mr[39;49m[38;5;124;43m'[39;49m[43m)[49m)
[1;32m      2[0m [38;5;28;01mfor[39;00m feature [38;5;129;01min[39;00m corop[[38;5;124m'[39m[38;5;124mfeatures[39m[38;5;124m'[39m]:
[1;32m      3[0m   feature[[38;5;124m'[39m[38;5;124mid[39m[38;5;124m'[39m] [38;5;241m=[39m feature[[38;5;124m'[39m[38;5;124mproperties[39m[38;5;124m'[39m][[38;5;124m'[39m[38;5;124mstatcode[39m[38;5;124m'[39m]

File [0;32m~/miniconda3/envs/jupyterbook/lib/python3.11/site-packages/IPython/core/interactiveshell.py:284[0m, in [0;36m_modified_open[0;34m(file, *args, **kwargs)[0m
[1;32m    277[0m [38;5;28;01mif[39;00m file [38;5;129;01min[39;00m {[38;5;241m0[39m, [38;5;241m1[39m, [38;5;241m2[39m}:
[1;32m    278[0m     [38;5;28;01mraise[39;00m [38;5;167;01mValueError[39;00m(
[1;32m    279[0m         [38;5;124mf[39m[38;5;124m"[39m[38;5;124mIPython won[39m[38;5;124m'[39m[38;5;124mt let you open fd=[39m[38;5;132;01m{[39;00mfile[38;5;132;01m}[39;00m[38;5;124m by default [39m[38;5;124m"[39m
[1;32m    280[0m         [38;5;124m"[39m[38;5;124mas it is likely to crash IPython. If you know what you are doing, [39m[38;5;124m"[39m
[1;32m    281[0m         [38;5;124m"[39m[38;5;124myou can use builtins[39m[38;5;124m'[39m[38;5;124m open.[39m[38;5;124m"[39m
[1;32m    282[0m     )
[0;32m--> 284[0m [38;5;28;01mreturn[39;00m [43mio_open[49m[43m([49m[43mfile[49m[43m,[49m[43m [49m[38;5;241;43m*[39;49m[43margs[49m[43m,[49m[43m [49m[38;5;241;43m*[39;49m[38;5;241;43m*[39;49m[43mkwargs[49m[43m)[49m

[0;31mFileNotFoundError[0m: [Errno 2] No such file or directory: 'coropgebied_gegeneraliseerd_2021.geojson'

